#VRML_SIM R2025a utf8

EXTERNPROTO "https://raw.githubusercontent.com/cyberbotics/webots/R2025a/projects/objects/backgrounds/protos/TexturedBackground.proto"
EXTERNPROTO "https://raw.githubusercontent.com/cyberbotics/webots/R2025a/projects/objects/backgrounds/protos/TexturedBackgroundLight.proto"
EXTERNPROTO "https://raw.githubusercontent.com/cyberbotics/webots/R2025a/projects/objects/floors/protos/RectangleArena.proto"
EXTERNPROTO "https://raw.githubusercontent.com/cyberbotics/webots/R2025a/projects/appearances/protos/Parquetry.proto"

WorldInfo {
}
Viewpoint {
  orientation -0.27607777895763275 -0.6735290042299414 0.6856673686466669 5.323837451021542
  position -0.4992731773174277 0.11246818407610482 1.1051975799557228
}
TexturedBackground {
}
TexturedBackgroundLight {
}
RectangleArena {
  floorSize 2 2
  floorAppearance Parquetry {
    type "light strip"
  }
}
Robot {
  translation 0.40689829473662875 -0.11208777064914391 0.03203302753180501
  rotation 0.12141249606446426 0.7018039210422833 0.7019474782411239 2.9015918441616013
  children [
    Pose {
      children [
        Pose {
          translation 0 -0.02 0
          children [
            Shape {
              appearance PBRAppearance {
                baseColor 0.8 0.8 0.8
                roughness 0.9
              }
              geometry Box {
                size 0.18 0.01 0.13
              }
            }
          ]
        }
        Pose {
          translation 0 0.005 0.06
          children [
            Shape {
              appearance PBRAppearance {
                baseColor 0.8 0.8 0.8
                roughness 0.9
              }
              geometry Box {
                size 0.18 0.04 0.01
              }
            }
          ]
        }
        Pose {
          translation 0 0.005 -0.06
          children [
            Shape {
              appearance PBRAppearance {
                baseColor 0.8 0.8 0.8
                roughness 0.9
              }
              geometry Box {
                size 0.18 0.04 0.01
              }
            }
          ]
        }
        Pose {
          translation 0.085 0.005 0
          children [
            Shape {
              appearance PBRAppearance {
                baseColor 0.8 0.8 0.8
                roughness 0.9
              }
              geometry Box {
                size 0.01 0.04 0.11
              }
            }
          ]
        }
        Pose {
          translation -0.085 0.005 0
          children [
            Shape {
              appearance PBRAppearance {
                baseColor 0.8 0.8 0.8
                roughness 0.9
              }
              geometry Box {
                size 0.01 0.04 0.11
              }
            }
          ]
        }
        Pose {
          translation 0.06 0.03 0
          children [
            Shape {
              appearance PBRAppearance {
                baseColor 0.8 0.8 0.8
                roughness 0.9
              }
              geometry Box {
                size 0.06 0.01 0.13
              }
            }
          ]
        }
        Pose {
          translation -0.06 0.03 0
          children [
            Shape {
              appearance PBRAppearance {
                baseColor 0.8 0.8 0.8
                roughness 0.9
              }
              geometry Box {
                size 0.06 0.01 0.13
              }
            }
          ]
        }
        Pose {
          translation 0 0.03 0.045
          children [
            Shape {
              appearance PBRAppearance {
                baseColor 0.8 0.8 0.8
                roughness 0.9
              }
              geometry Box {
                size 0.06 0.01 0.04
              }
            }
          ]
        }
        Pose {
          translation 0 0.03 -0.045
          children [
            Shape {
              appearance PBRAppearance {
                baseColor 0.8 0.8 0.8
                roughness 0.9
              }
              geometry Box {
                size 0.06 0.01 0.04
              }
            }
          ]
        }
        Pose {
          translation -0.015 -0.01 0
          children [
            Shape {
              appearance PBRAppearance {
                baseColor 0.1 0.3 0.8
                roughness 0.5
                metalness 0.2
              }
              geometry Box {
                size 0.05 0.005 0.04
              }
            }
          ]
        }
        Pose {
          translation 0.02 -0.01 0
          children [
            Shape {
              appearance PBRAppearance {
                baseColor 0.1 0.3 0.8
                roughness 0.5
                metalness 0.2
              }
              geometry Box {
                size 0.04 0.005 0.03
              }
            }
          ]
        }
        Pose {
          translation -0.015 -0.005 0.015
          children [
            Shape {
              appearance PBRAppearance {
                baseColor 0.1 0.1 0.1
                roughness 0.8
              }
              geometry Box {
                size 0.04 0.005 0.005
              }
            }
          ]
        }
      ]
    }
    Solid {
      translation -0.05 0.035 0
      rotation 0 1 0 3.14159
      children [
        Shape {
          appearance PBRAppearance {
            baseColor 0.6 0.6 0.6
            roughness 1
          }
          geometry Box {
            size 0.06 0.08 0.06
          }
        }
        HingeJoint {
          jointParameters HingeJointParameters {
            position 1.1323775694721938e-17
            axis 0 1 0
            anchor 0 0.04 0
          }
          device [
            RotationalMotor {
              name "pan_motor"
            }
          ]
          endPoint Solid {
            translation 0 0.04 0
            rotation 0.49549864281257605 -0.8290696245752907 -0.25908425767977833 1.071295333193656e-15
            children [
              HingeJoint {
                jointParameters HingeJointParameters {
                  axis 0 0 1
                  anchor 0 0.02 0
                }
                device [
                  RotationalMotor {
                    name "tilt_motor"
                  }
                ]
                endPoint Camera {
                  translation 0.015000000000000005 0.02 0
                  children [
                    Pose {
                      translation -0.002 0 0
                      children [
                        Shape {
                          appearance PBRAppearance {
                            baseColor 0.1 0.6 0.2
                            roughness 0.5
                          }
                          geometry Box {
                            size 0.002 0.024 0.024
                          }
                        }
                      ]
                    }
                    Pose {
                      translation 0.002 0 0
                      rotation 0 0 1 1.5708
                      children [
                        Shape {
                          appearance PBRAppearance {
                            baseColor 0.05 0.05 0.05
                            roughness 0.2
                          }
                          geometry Cylinder {
                            height 0.008
                            radius 0.005
                          }
                        }
                      ]
                    }
                  ]
                  fieldOfView 1
                  width 640
                  height 480
                }
              }
            ]
            name "pan_link"
            boundingObject Box {
              size 0.02 0.02 0.02
            }
            physics Physics {
            }
            linearVelocity 2.4340337738324055e-17 -3.426892026506308e-16 -1.1102209070427919e-16
            angularVelocity 6.42340225722771e-15 -1.340479667194853e-15 1.3332641440791314e-15
          }
        }
      ]
      name "tower"
      boundingObject Box {
        size 0.06 0.08 0.06
      }
      physics Physics {
      }
    }
    HingeJoint {
      jointParameters HingeJointParameters {
        position -3.6022296305558053
        axis 0 0 1
        anchor 0.05 0 0.08
      }
      device [
        RotationalMotor {
          name "wheel1"
        }
      ]
      endPoint Solid {
        translation 0.05 0 0.08
        rotation 0 0 -0.9999999999999999 3.6022296305558053
        children [
          DEF WHEEL_SHAPE Group {
            children [
              Pose {
                children [
                  Shape {
                    appearance PBRAppearance {
                      baseColor 1 0.9 0.1
                      roughness 0.6
                    }
                    geometry Cylinder {
                      height 0.026
                      radius 0.028
                    }
                  }
                ]
              }
              Pose {
                children [
                  Shape {
                    appearance PBRAppearance {
                      baseColor 0.1 0.1 0.1
                      roughness 0.9
                    }
                    geometry Cylinder {
                      height 0.022
                      radius 0.0325
                    }
                  }
                ]
              }
            ]
          }
        ]
        name "wheel1_solid"
        boundingObject USE WHEEL_SHAPE
        physics Physics {
        }
        linearVelocity 2.632908182368088e-16 -1.8619987583716517e-16 -3.110903881237399e-16
        angularVelocity 4.984196240603278e-15 2.0844642042520273e-15 1.4350285222985973e-15
      }
    }
    HingeJoint {
      jointParameters HingeJointParameters {
        position 14.016885630306959
        axis 0 0 1
        anchor 0.05 0 -0.08
      }
      device [
        RotationalMotor {
          name "wheel2"
        }
      ]
      endPoint Solid {
        translation 0.05 0 -0.08
        rotation 6.694864369077443e-16 -5.439577299875423e-16 1 1.4505150159477858
        children [
          USE WHEEL_SHAPE
        ]
        name "wheel2_solid"
        boundingObject USE WHEEL_SHAPE
        physics Physics {
        }
        linearVelocity 3.131577482947577e-16 -3.432743456897113e-16 4.1479328710636445e-16
        angularVelocity 8.654051668320535e-15 -2.959986270697387e-15 1.7256123799948574e-15
      }
    }
    HingeJoint {
      jointParameters HingeJointParameters {
        position -3.6022731798863354
        axis 0 0 1
        anchor -0.05 0 0.08
      }
      device [
        RotationalMotor {
          name "wheel3"
        }
      ]
      endPoint Solid {
        translation -0.05 0 0.08
        rotation 0 0 -1 3.6022731798863354
        children [
          USE WHEEL_SHAPE
        ]
        name "wheel3_solid"
        boundingObject USE WHEEL_SHAPE
        physics Physics {
        }
        linearVelocity -2.6991707074486874e-16 2.2885055295982097e-16 1.0370051676945765e-16
        angularVelocity -1.7489296524118574e-14 6.856384787374973e-15 1.068346949596654e-15
      }
    }
    HingeJoint {
      jointParameters HingeJointParameters {
        position 14.016841444690778
        axis 0 0 1
        anchor -0.05 0 -0.08
      }
      device [
        RotationalMotor {
          name "wheel4"
        }
      ]
      endPoint Solid {
        translation -0.05 0 -0.08
        rotation 1.5900699186822406e-15 -1.6737578091392007e-15 1 1.4504708303316036
        children [
          USE WHEEL_SHAPE
        ]
        name "wheel4_solid"
        boundingObject USE WHEEL_SHAPE
        physics Physics {
        }
        linearVelocity -4.211182925389867e-16 -3.1439894709321365e-16 -3.6800460373584845e-21
        angularVelocity 1.8119353514109827e-16 -9.36412934722835e-16 9.882708038296537e-16
      }
    }
  ]
  name "smart_robot"
  boundingObject Pose {
    translation 0 0.005 0
    children [
      Box {
        size 0.18 0.05 0.13
      }
    ]
  }
  physics Physics {
    density -1
    mass 1.5
  }
  controller "smart_robot_controller"
  linearVelocity 4.025620836864735e-16 -2.19864679416035e-16 -1.271664851472215e-16
  angularVelocity -5.325936901674653e-16 4.0037840578060183e-16 1.2196910144652984e-15
}
Solid {
  translation 0.5 -0.5 0.04985312452985144
  children [
    Shape {
      appearance PBRAppearance {
        baseColor 1 0 0
        roughness 0.5
      }
      geometry Sphere {
        radius 0.05
      }
    }
  ]
  name "red_ball"
  boundingObject Sphere {
    radius 0.05
  }
  physics Physics {
    density -1
    mass 0.1
  }
  linearVelocity 0 0 -7.885319095329635e-05
}
